[2024-02-29 21:57:35 +0000] [37866] [INFO] Starting gunicorn 21.2.0
[2024-02-29 21:57:35 +0000] [37866] [INFO] Listening at: http://0.0.0.0:8000 (37866)
[2024-02-29 21:57:35 +0000] [37866] [INFO] Using worker: sync
[2024-02-29 21:57:35 +0000] [37869] [INFO] Booting worker with pid: 37869
[2024-02-29 22:01:16 +0000] [37866] [INFO] Handling signal: hup
[2024-02-29 22:01:16 +0000] [37866] [INFO] Hang up: Master
[2024-02-29 22:01:16 +0000] [37869] [INFO] Worker exiting (pid: 37869)
2024-02-29 04:57:42 PM
[2024-02-29 22:01:16 +0000] [37866] [ERROR] Worker (pid:37869) was sent SIGTERM!
[2024-02-29 22:01:16 +0000] [38165] [INFO] Booting worker with pid: 38165
[2024-02-29 22:01:19 +0000] [37866] [INFO] Handling signal: hup
[2024-02-29 22:01:19 +0000] [37866] [INFO] Hang up: Master
[2024-02-29 22:01:19 +0000] [38165] [INFO] Worker exiting (pid: 38165)
[2024-02-29 22:01:19 +0000] [41428] [INFO] Booting worker with pid: 41428
[2024-02-29 22:01:19 +0000] [37866] [ERROR] Worker (pid:38165) was sent SIGTERM!
[2024-02-29 22:01:19 +0000] [37866] [INFO] Handling signal: hup
[2024-02-29 22:01:19 +0000] [37866] [INFO] Hang up: Master
[2024-02-29 22:01:19 +0000] [41428] [INFO] Worker exiting (pid: 41428)
[2024-02-29 22:01:19 +0000] [37866] [ERROR] Worker (pid:41428) was sent SIGTERM!
[2024-02-29 22:01:19 +0000] [42408] [INFO] Booting worker with pid: 42408
[2024-02-29 22:01:20 +0000] [37866] [INFO] Handling signal: hup
[2024-02-29 22:01:20 +0000] [37866] [INFO] Hang up: Master
[2024-02-29 22:01:20 +0000] [42408] [INFO] Worker exiting (pid: 42408)
[2024-02-29 22:01:20 +0000] [37866] [ERROR] Worker (pid:42408) was sent SIGTERM!
[2024-02-29 22:01:20 +0000] [42857] [INFO] Booting worker with pid: 42857
[2024-02-29 22:01:25 +0000] [37866] [INFO] Handling signal: hup
[2024-02-29 22:01:25 +0000] [37866] [INFO] Hang up: Master
[2024-02-29 22:01:25 +0000] [42857] [INFO] Worker exiting (pid: 42857)
[2024-02-29 22:01:25 +0000] [37866] [ERROR] Worker (pid:42857) was sent SIGTERM!
[2024-02-29 22:01:25 +0000] [48862] [INFO] Booting worker with pid: 48862
[2024-02-29 22:09:15 +0000] [37866] [INFO] Handling signal: hup
[2024-02-29 22:09:15 +0000] [37866] [INFO] Hang up: Master
[2024-02-29 22:09:15 +0000] [48862] [INFO] Worker exiting (pid: 48862)
2024-02-29 05:05:00 PM
[2024-02-29 22:09:15 +0000] [51455] [INFO] Booting worker with pid: 51455
[2024-02-29 22:09:15 +0000] [37866] [ERROR] Worker (pid:48862) was sent SIGTERM!
[2024-02-29 22:09:15 +0000] [37866] [INFO] Handling signal: hup
[2024-02-29 22:09:15 +0000] [37866] [INFO] Hang up: Master
[2024-02-29 22:09:15 +0000] [37866] [INFO] Handling signal: hup
[2024-02-29 22:09:15 +0000] [37866] [INFO] Hang up: Master
[2024-02-29 22:09:15 +0000] [51467] [INFO] Booting worker with pid: 51467
[2024-02-29 22:09:15 +0000] [51469] [INFO] Booting worker with pid: 51469
[2024-02-29 22:09:16 +0000] [51455] [INFO] Worker exiting (pid: 51455)
[2024-02-29 22:09:16 +0000] [51467] [INFO] Worker exiting (pid: 51467)
[2024-02-29 22:09:16 +0000] [37866] [ERROR] Worker (pid:51467) was sent SIGTERM!
[2024-02-29 22:09:17 +0000] [37866] [INFO] Handling signal: hup
[2024-02-29 22:09:17 +0000] [37866] [INFO] Hang up: Master
[2024-02-29 22:09:17 +0000] [51469] [INFO] Worker exiting (pid: 51469)
[2024-02-29 22:09:17 +0000] [51501] [INFO] Booting worker with pid: 51501
[2024-02-29 22:09:17 +0000] [37866] [INFO] Handling signal: hup
[2024-02-29 22:09:17 +0000] [37866] [INFO] Hang up: Master
[2024-02-29 22:09:17 +0000] [37866] [INFO] Handling signal: hup
--- Logging error ---
[2024-02-29 22:09:17 +0000] [51514] [INFO] Booting worker with pid: 51514
Traceback (most recent call last):
  File "/usr/lib/python3.10/logging/__init__.py", line 1103, in emit
    stream.write(msg + self.terminator)
RuntimeError: reentrant call inside <_io.BufferedWriter name='<stderr>'>

During handling of the above exception, another exception occurred:

Traceback (most recent call last):
  File "/usr/lib/python3.10/logging/__init__.py", line 1103, in emit
    stream.write(msg + self.terminator)
  File "/usr/local/lib/python3.10/dist-packages/gunicorn/arbiter.py", line 242, in handle_chld
    self.reap_workers()
  File "/usr/local/lib/python3.10/dist-packages/gunicorn/arbiter.py", line 554, in reap_workers
    self.log.error(msg)
  File "/usr/local/lib/python3.10/dist-packages/gunicorn/glogging.py", line 272, in error
    self.error_log.error(msg, *args, **kwargs)
  File "/usr/lib/python3.10/logging/__init__.py", line 1506, in error
    self._log(ERROR, msg, args, **kwargs)
  File "/usr/lib/python3.10/logging/__init__.py", line 1624, in _log
    self.handle(record)
  File "/usr/lib/python3.10/logging/__init__.py", line 1634, in handle
    self.callHandlers(record)
  File "/usr/lib/python3.10/logging/__init__.py", line 1696, in callHandlers
    hdlr.handle(record)
  File "/usr/lib/python3.10/logging/__init__.py", line 968, in handle
    self.emit(record)
  File "/usr/lib/python3.10/logging/__init__.py", line 1108, in emit
    self.handleError(record)
  File "/usr/lib/python3.10/logging/__init__.py", line 1021, in handleError
    sys.stderr.write('--- Logging error ---\n')
RuntimeError: reentrant call inside <_io.BufferedWriter name='<stderr>'>
Call stack:
  File "/usr/local/bin/gunicorn", line 8, in <module>
    sys.exit(run())
  File "/usr/local/lib/python3.10/dist-packages/gunicorn/app/wsgiapp.py", line 67, in run
    WSGIApplication("%(prog)s [OPTIONS] [APP_MODULE]").run()
  File "/usr/local/lib/python3.10/dist-packages/gunicorn/app/base.py", line 236, in run
    super().run()
  File "/usr/local/lib/python3.10/dist-packages/gunicorn/app/base.py", line 72, in run
    Arbiter(self).run()
  File "/usr/local/lib/python3.10/dist-packages/gunicorn/arbiter.py", line 223, in run
    self.log.info("Handling signal: %s", signame)
  File "/usr/local/lib/python3.10/dist-packages/gunicorn/glogging.py", line 278, in info
    self.error_log.info(msg, *args, **kwargs)
Message: 'Handling signal: %s'
Arguments: ('hup',)
[2024-02-29 22:09:17 +0000] [37866] [INFO] Hang up: Master
[2024-02-29 22:09:17 +0000] [51515] [INFO] Booting worker with pid: 51515
[2024-02-29 22:09:17 +0000] [51501] [INFO] Worker exiting (pid: 51501)
[2024-02-29 22:09:17 +0000] [51514] [INFO] Worker exiting (pid: 51514)
[2024-02-29 22:09:17 +0000] [37866] [ERROR] Worker (pid:51514) was sent SIGTERM!
[2024-02-29 22:10:25 +0000] [37866] [INFO] Handling signal: hup
[2024-02-29 22:10:25 +0000] [37866] [INFO] Hang up: Master
[2024-02-29 22:10:25 +0000] [51515] [INFO] Worker exiting (pid: 51515)
[2024-02-29 22:10:25 +0000] [37866] [INFO] Handling signal: hup
[2024-02-29 22:10:25 +0000] [37866] [INFO] Hang up: Master
[2024-02-29 22:10:25 +0000] [51567] [INFO] Booting worker with pid: 51567
[2024-02-29 22:10:25 +0000] [37866] [ERROR] Worker (pid:51515) was sent SIGTERM!
[2024-02-29 22:10:25 +0000] [37866] [INFO] Handling signal: hup
[2024-02-29 22:10:25 +0000] [37866] [INFO] Hang up: Master
[2024-02-29 22:10:25 +0000] [51580] [INFO] Booting worker with pid: 51580
[2024-02-29 22:10:25 +0000] [51581] [INFO] Booting worker with pid: 51581
[2024-02-29 22:10:25 +0000] [51567] [INFO] Worker exiting (pid: 51567)
[2024-02-29 22:10:25 +0000] [51580] [INFO] Worker exiting (pid: 51580)
[2024-02-29 22:10:25 +0000] [37866] [ERROR] Worker (pid:51580) was sent SIGTERM!
[2024-02-29 22:10:36 +0000] [37866] [INFO] Handling signal: hup
[2024-02-29 22:10:36 +0000] [37866] [INFO] Hang up: Master
[2024-02-29 22:10:36 +0000] [51581] [INFO] Worker exiting (pid: 51581)
[2024-02-29 22:10:36 +0000] [51644] [INFO] Booting worker with pid: 51644
[2024-02-29 22:10:36 +0000] [37866] [INFO] Handling signal: hup
[2024-02-29 22:10:36 +0000] [37866] [INFO] Hang up: Master
[2024-02-29 22:10:36 +0000] [37866] [INFO] Handling signal: hup
--- Logging error ---
Traceback (most recent call last):
  File "/usr/lib/python3.10/logging/__init__.py", line 1103, in emit
    stream.write(msg + self.terminator)
RuntimeError: reentrant call inside <_io.BufferedWriter name='<stderr>'>

During handling of the above exception, another exception occurred:

Traceback (most recent call last):
  File "/usr/lib/python3.10/logging/__init__.py", line 1103, in emit
    stream.write(msg + self.terminator)
  File "/usr/local/lib/python3.10/dist-packages/gunicorn/arbiter.py", line 242, in handle_chld
    self.reap_workers()
  File "/usr/local/lib/python3.10/dist-packages/gunicorn/arbiter.py", line 554, in reap_workers
    self.log.error(msg)
  File "/usr/local/lib/python3.10/dist-packages/gunicorn/glogging.py", line 272, in error
    self.error_log.error(msg, *args, **kwargs)
  File "/usr/lib/python3.10/logging/__init__.py", line 1506, in error
    self._log(ERROR, msg, args, **kwargs)
  File "/usr/lib/python3.10/logging/__init__.py", line 1624, in _log
    self.handle(record)
  File "/usr/lib/python3.10/logging/__init__.py", line 1634, in handle
    self.callHandlers(record)
  File "/usr/lib/python3.10/logging/__init__.py", line 1696, in callHandlers
    hdlr.handle(record)
  File "/usr/lib/python3.10/logging/__init__.py", line 968, in handle
    self.emit(record)
  File "/usr/lib/python3.10/logging/__init__.py", line 1108, in emit
    self.handleError(record)
  File "/usr/lib/python3.10/logging/__init__.py", line 1021, in handleError
    sys.stderr.write('--- Logging error ---\n')
RuntimeError: reentrant call inside <_io.BufferedWriter name='<stderr>'>
Call stack:
  File "/usr/local/bin/gunicorn", line 8, in <module>
    sys.exit(run())
  File "/usr/local/lib/python3.10/dist-packages/gunicorn/app/wsgiapp.py", line 67, in run
    WSGIApplication("%(prog)s [OPTIONS] [APP_MODULE]").run()
  File "/usr/local/lib/python3.10/dist-packages/gunicorn/app/base.py", line 236, in run
    super().run()
  File "/usr/local/lib/python3.10/dist-packages/gunicorn/app/base.py", line 72, in run
    Arbiter(self).run()
  File "/usr/local/lib/python3.10/dist-packages/gunicorn/arbiter.py", line 223, in run
    self.log.info("Handling signal: %s", signame)
  File "/usr/local/lib/python3.10/dist-packages/gunicorn/glogging.py", line 278, in info
    self.error_log.info(msg, *args, **kwargs)
Message: 'Handling signal: %s'
Arguments: ('hup',)
[2024-02-29 22:10:36 +0000] [37866] [INFO] Hang up: Master
[2024-02-29 22:10:36 +0000] [51656] [INFO] Booting worker with pid: 51656
[2024-02-29 22:10:36 +0000] [51657] [INFO] Booting worker with pid: 51657
[2024-02-29 22:10:36 +0000] [51644] [INFO] Worker exiting (pid: 51644)
[2024-02-29 22:10:36 +0000] [51656] [INFO] Worker exiting (pid: 51656)
[2024-02-29 22:11:02 +0000] [37866] [INFO] Handling signal: hup
[2024-02-29 22:11:02 +0000] [37866] [INFO] Hang up: Master
[2024-02-29 22:11:02 +0000] [51657] [INFO] Worker exiting (pid: 51657)
[2024-02-29 22:11:02 +0000] [37866] [INFO] Handling signal: hup
[2024-02-29 22:11:02 +0000] [37866] [INFO] Hang up: Master
[2024-02-29 22:11:02 +0000] [51761] [INFO] Booting worker with pid: 51761
[2024-02-29 22:11:02 +0000] [37866] [ERROR] Worker (pid:51657) was sent SIGTERM!
[2024-02-29 22:11:02 +0000] [37866] [INFO] Handling signal: hup
[2024-02-29 22:11:02 +0000] [37866] [INFO] Hang up: Master
[2024-02-29 22:11:02 +0000] [51771] [INFO] Booting worker with pid: 51771
[2024-02-29 22:11:02 +0000] [37866] [INFO] Handling signal: hup
[2024-02-29 22:11:02 +0000] [37866] [INFO] Hang up: Master
[2024-02-29 22:11:02 +0000] [51772] [INFO] Booting worker with pid: 51772
[2024-02-29 22:11:02 +0000] [51773] [INFO] Booting worker with pid: 51773
[2024-02-29 22:11:03 +0000] [51761] [INFO] Worker exiting (pid: 51761)
[2024-02-29 22:11:03 +0000] [51771] [INFO] Worker exiting (pid: 51771)
[2024-02-29 22:11:03 +0000] [51772] [INFO] Worker exiting (pid: 51772)
[2024-02-29 22:11:03 +0000] [37866] [ERROR] Worker (pid:51771) was sent SIGTERM!
[2024-02-29 22:11:03 +0000] [37866] [ERROR] Worker (pid:51772) was sent SIGTERM!
[2024-02-29 22:18:19 +0000] [51773] [ERROR] Error handling request /
Traceback (most recent call last):
  File "/usr/local/lib/python3.10/dist-packages/django/core/handlers/exception.py", line 55, in inner
    response = get_response(request)
  File "/usr/local/lib/python3.10/dist-packages/django/core/handlers/base.py", line 181, in _get_response
    callback, callback_args, callback_kwargs = self.resolve_request(request)
  File "/usr/local/lib/python3.10/dist-packages/django/core/handlers/base.py", line 313, in resolve_request
    resolver_match = resolver.resolve(request.path_info)
  File "/usr/local/lib/python3.10/dist-packages/django/urls/resolvers.py", line 686, in resolve
    for pattern in self.url_patterns:
  File "/usr/local/lib/python3.10/dist-packages/django/utils/functional.py", line 47, in __get__
    res = instance.__dict__[self.name] = self.func(instance)
  File "/usr/local/lib/python3.10/dist-packages/django/urls/resolvers.py", line 738, in url_patterns
    patterns = getattr(self.urlconf_module, "urlpatterns", self.urlconf_module)
  File "/usr/local/lib/python3.10/dist-packages/django/utils/functional.py", line 47, in __get__
    res = instance.__dict__[self.name] = self.func(instance)
  File "/usr/local/lib/python3.10/dist-packages/django/urls/resolvers.py", line 731, in urlconf_module
    return import_module(self.urlconf_name)
  File "/usr/lib/python3.10/importlib/__init__.py", line 126, in import_module
    return _bootstrap._gcd_import(name[level:], package, level)
  File "<frozen importlib._bootstrap>", line 1050, in _gcd_import
  File "<frozen importlib._bootstrap>", line 1027, in _find_and_load
  File "<frozen importlib._bootstrap>", line 1006, in _find_and_load_unlocked
  File "<frozen importlib._bootstrap>", line 688, in _load_unlocked
  File "<frozen importlib._bootstrap_external>", line 883, in exec_module
  File "<frozen importlib._bootstrap>", line 241, in _call_with_frames_removed
  File "/debtfreesolutions/FullRealEstateProject/FullRealEstateProject/urls.py", line 22, in <module>
    path('', include('viewer.urls')),  # replace 'your_app_name' with the name of your app
  File "/usr/local/lib/python3.10/dist-packages/django/urls/conf.py", line 39, in include
    urlconf_module = import_module(urlconf_module)
  File "/usr/lib/python3.10/importlib/__init__.py", line 126, in import_module
    return _bootstrap._gcd_import(name[level:], package, level)
  File "<frozen importlib._bootstrap>", line 1050, in _gcd_import
  File "<frozen importlib._bootstrap>", line 1027, in _find_and_load
  File "<frozen importlib._bootstrap>", line 1006, in _find_and_load_unlocked
  File "<frozen importlib._bootstrap>", line 688, in _load_unlocked
  File "<frozen importlib._bootstrap_external>", line 883, in exec_module
  File "<frozen importlib._bootstrap>", line 241, in _call_with_frames_removed
  File "/debtfreesolutions/FullRealEstateProject/viewer/urls.py", line 2, in <module>
    from . import views
  File "/debtfreesolutions/FullRealEstateProject/viewer/views.py", line 13
    echo "Starting Gunicorn..."
         ^^^^^^^^^^^^^^^^^^^^^^
SyntaxError: invalid syntax

During handling of the above exception, another exception occurred:

Traceback (most recent call last):
  File "/usr/local/lib/python3.10/dist-packages/django/core/handlers/exception.py", line 55, in inner
    response = get_response(request)
  File "/usr/local/lib/python3.10/dist-packages/django/utils/deprecation.py", line 134, in __call__
    response = response or self.get_response(request)
  File "/usr/local/lib/python3.10/dist-packages/django/core/handlers/exception.py", line 57, in inner
    response = response_for_exception(request, exc)
  File "/usr/local/lib/python3.10/dist-packages/django/core/handlers/exception.py", line 140, in response_for_exception
    response = handle_uncaught_exception(
  File "/usr/local/lib/python3.10/dist-packages/django/core/handlers/exception.py", line 184, in handle_uncaught_exception
    callback = resolver.resolve_error_handler(500)
  File "/usr/local/lib/python3.10/dist-packages/django/urls/resolvers.py", line 752, in resolve_error_handler
    callback = getattr(self.urlconf_module, "handler%s" % view_type, None)
  File "/usr/local/lib/python3.10/dist-packages/django/utils/functional.py", line 47, in __get__
    res = instance.__dict__[self.name] = self.func(instance)
  File "/usr/local/lib/python3.10/dist-packages/django/urls/resolvers.py", line 731, in urlconf_module
    return import_module(self.urlconf_name)
  File "/usr/lib/python3.10/importlib/__init__.py", line 126, in import_module
    return _bootstrap._gcd_import(name[level:], package, level)
  File "<frozen importlib._bootstrap>", line 1050, in _gcd_import
  File "<frozen importlib._bootstrap>", line 1027, in _find_and_load
  File "<frozen importlib._bootstrap>", line 1006, in _find_and_load_unlocked
  File "<frozen importlib._bootstrap>", line 688, in _load_unlocked
  File "<frozen importlib._bootstrap_external>", line 883, in exec_module
  File "<frozen importlib._bootstrap>", line 241, in _call_with_frames_removed
  File "/debtfreesolutions/FullRealEstateProject/FullRealEstateProject/urls.py", line 22, in <module>
    path('', include('viewer.urls')),  # replace 'your_app_name' with the name of your app
  File "/usr/local/lib/python3.10/dist-packages/django/urls/conf.py", line 39, in include
    urlconf_module = import_module(urlconf_module)
  File "/usr/lib/python3.10/importlib/__init__.py", line 126, in import_module
    return _bootstrap._gcd_import(name[level:], package, level)
  File "<frozen importlib._bootstrap>", line 1050, in _gcd_import
  File "<frozen importlib._bootstrap>", line 1027, in _find_and_load
  File "<frozen importlib._bootstrap>", line 1006, in _find_and_load_unlocked
  File "<frozen importlib._bootstrap>", line 688, in _load_unlocked
  File "<frozen importlib._bootstrap_external>", line 883, in exec_module
  File "<frozen importlib._bootstrap>", line 241, in _call_with_frames_removed
  File "/debtfreesolutions/FullRealEstateProject/viewer/urls.py", line 2, in <module>
    from . import views
  File "/debtfreesolutions/FullRealEstateProject/viewer/views.py", line 13
    echo "Starting Gunicorn..."
         ^^^^^^^^^^^^^^^^^^^^^^
SyntaxError: invalid syntax

During handling of the above exception, another exception occurred:

Traceback (most recent call last):
  File "/usr/local/lib/python3.10/dist-packages/django/core/handlers/exception.py", line 55, in inner
    response = get_response(request)
  File "/usr/local/lib/python3.10/dist-packages/django/utils/deprecation.py", line 134, in __call__
    response = response or self.get_response(request)
  File "/usr/local/lib/python3.10/dist-packages/django/core/handlers/exception.py", line 57, in inner
    response = response_for_exception(request, exc)
  File "/usr/local/lib/python3.10/dist-packages/django/core/handlers/exception.py", line 140, in response_for_exception
    response = handle_uncaught_exception(
  File "/usr/local/lib/python3.10/dist-packages/django/core/handlers/exception.py", line 184, in handle_uncaught_exception
    callback = resolver.resolve_error_handler(500)
  File "/usr/local/lib/python3.10/dist-packages/django/urls/resolvers.py", line 752, in resolve_error_handler
    callback = getattr(self.urlconf_module, "handler%s" % view_type, None)
  File "/usr/local/lib/python3.10/dist-packages/django/utils/functional.py", line 47, in __get__
    res = instance.__dict__[self.name] = self.func(instance)
  File "/usr/local/lib/python3.10/dist-packages/django/urls/resolvers.py", line 731, in urlconf_module
    return import_module(self.urlconf_name)
  File "/usr/lib/python3.10/importlib/__init__.py", line 126, in import_module
    return _bootstrap._gcd_import(name[level:], package, level)
  File "<frozen importlib._bootstrap>", line 1050, in _gcd_import
  File "<frozen importlib._bootstrap>", line 1027, in _find_and_load
  File "<frozen importlib._bootstrap>", line 1006, in _find_and_load_unlocked
  File "<frozen importlib._bootstrap>", line 688, in _load_unlocked
  File "<frozen importlib._bootstrap_external>", line 883, in exec_module
  File "<frozen importlib._bootstrap>", line 241, in _call_with_frames_removed
  File "/debtfreesolutions/FullRealEstateProject/FullRealEstateProject/urls.py", line 22, in <module>
    path('', include('viewer.urls')),  # replace 'your_app_name' with the name of your app
  File "/usr/local/lib/python3.10/dist-packages/django/urls/conf.py", line 39, in include
    urlconf_module = import_module(urlconf_module)
  File "/usr/lib/python3.10/importlib/__init__.py", line 126, in import_module
    return _bootstrap._gcd_import(name[level:], package, level)
  File "<frozen importlib._bootstrap>", line 1050, in _gcd_import
  File "<frozen importlib._bootstrap>", line 1027, in _find_and_load
  File "<frozen importlib._bootstrap>", line 1006, in _find_and_load_unlocked
  File "<frozen importlib._bootstrap>", line 688, in _load_unlocked
  File "<frozen importlib._bootstrap_external>", line 883, in exec_module
  File "<frozen importlib._bootstrap>", line 241, in _call_with_frames_removed
  File "/debtfreesolutions/FullRealEstateProject/viewer/urls.py", line 2, in <module>
    from . import views
  File "/debtfreesolutions/FullRealEstateProject/viewer/views.py", line 13
    echo "Starting Gunicorn..."
         ^^^^^^^^^^^^^^^^^^^^^^
SyntaxError: invalid syntax

During handling of the above exception, another exception occurred:

Traceback (most recent call last):
  File "/usr/local/lib/python3.10/dist-packages/django/core/handlers/exception.py", line 55, in inner
    response = get_response(request)
  File "/usr/local/lib/python3.10/dist-packages/django/utils/deprecation.py", line 134, in __call__
    response = response or self.get_response(request)
  File "/usr/local/lib/python3.10/dist-packages/django/core/handlers/exception.py", line 57, in inner
    response = response_for_exception(request, exc)
  File "/usr/local/lib/python3.10/dist-packages/django/core/handlers/exception.py", line 140, in response_for_exception
    response = handle_uncaught_exception(
  File "/usr/local/lib/python3.10/dist-packages/django/core/handlers/exception.py", line 184, in handle_uncaught_exception
    callback = resolver.resolve_error_handler(500)
  File "/usr/local/lib/python3.10/dist-packages/django/urls/resolvers.py", line 752, in resolve_error_handler
    callback = getattr(self.urlconf_module, "handler%s" % view_type, None)
  File "/usr/local/lib/python3.10/dist-packages/django/utils/functional.py", line 47, in __get__
    res = instance.__dict__[self.name] = self.func(instance)
  File "/usr/local/lib/python3.10/dist-packages/django/urls/resolvers.py", line 731, in urlconf_module
    return import_module(self.urlconf_name)
  File "/usr/lib/python3.10/importlib/__init__.py", line 126, in import_module
    return _bootstrap._gcd_import(name[level:], package, level)
  File "<frozen importlib._bootstrap>", line 1050, in _gcd_import
  File "<frozen importlib._bootstrap>", line 1027, in _find_and_load
  File "<frozen importlib._bootstrap>", line 1006, in _find_and_load_unlocked
  File "<frozen importlib._bootstrap>", line 688, in _load_unlocked
  File "<frozen importlib._bootstrap_external>", line 883, in exec_module
  File "<frozen importlib._bootstrap>", line 241, in _call_with_frames_removed
  File "/debtfreesolutions/FullRealEstateProject/FullRealEstateProject/urls.py", line 22, in <module>
    path('', include('viewer.urls')),  # replace 'your_app_name' with the name of your app
  File "/usr/local/lib/python3.10/dist-packages/django/urls/conf.py", line 39, in include
    urlconf_module = import_module(urlconf_module)
  File "/usr/lib/python3.10/importlib/__init__.py", line 126, in import_module
    return _bootstrap._gcd_import(name[level:], package, level)
  File "<frozen importlib._bootstrap>", line 1050, in _gcd_import
  File "<frozen importlib._bootstrap>", line 1027, in _find_and_load
  File "<frozen importlib._bootstrap>", line 1006, in _find_and_load_unlocked
  File "<frozen importlib._bootstrap>", line 688, in _load_unlocked
  File "<frozen importlib._bootstrap_external>", line 883, in exec_module
  File "<frozen importlib._bootstrap>", line 241, in _call_with_frames_removed
  File "/debtfreesolutions/FullRealEstateProject/viewer/urls.py", line 2, in <module>
    from . import views
  File "/debtfreesolutions/FullRealEstateProject/viewer/views.py", line 13
    echo "Starting Gunicorn..."
         ^^^^^^^^^^^^^^^^^^^^^^
SyntaxError: invalid syntax

During handling of the above exception, another exception occurred:

Traceback (most recent call last):
  File "/usr/local/lib/python3.10/dist-packages/django/core/handlers/exception.py", line 55, in inner
    response = get_response(request)
  File "/usr/local/lib/python3.10/dist-packages/django/utils/deprecation.py", line 134, in __call__
    response = response or self.get_response(request)
  File "/usr/local/lib/python3.10/dist-packages/django/core/handlers/exception.py", line 57, in inner
    response = response_for_exception(request, exc)
  File "/usr/local/lib/python3.10/dist-packages/django/core/handlers/exception.py", line 140, in response_for_exception
    response = handle_uncaught_exception(
  File "/usr/local/lib/python3.10/dist-packages/django/core/handlers/exception.py", line 184, in handle_uncaught_exception
    callback = resolver.resolve_error_handler(500)
  File "/usr/local/lib/python3.10/dist-packages/django/urls/resolvers.py", line 752, in resolve_error_handler
    callback = getattr(self.urlconf_module, "handler%s" % view_type, None)
  File "/usr/local/lib/python3.10/dist-packages/django/utils/functional.py", line 47, in __get__
    res = instance.__dict__[self.name] = self.func(instance)
  File "/usr/local/lib/python3.10/dist-packages/django/urls/resolvers.py", line 731, in urlconf_module
    return import_module(self.urlconf_name)
  File "/usr/lib/python3.10/importlib/__init__.py", line 126, in import_module
    return _bootstrap._gcd_import(name[level:], package, level)
  File "<frozen importlib._bootstrap>", line 1050, in _gcd_import
  File "<frozen importlib._bootstrap>", line 1027, in _find_and_load
  File "<frozen importlib._bootstrap>", line 1006, in _find_and_load_unlocked
  File "<frozen importlib._bootstrap>", line 688, in _load_unlocked
  File "<frozen importlib._bootstrap_external>", line 883, in exec_module
  File "<frozen importlib._bootstrap>", line 241, in _call_with_frames_removed
  File "/debtfreesolutions/FullRealEstateProject/FullRealEstateProject/urls.py", line 22, in <module>
    path('', include('viewer.urls')),  # replace 'your_app_name' with the name of your app
  File "/usr/local/lib/python3.10/dist-packages/django/urls/conf.py", line 39, in include
    urlconf_module = import_module(urlconf_module)
  File "/usr/lib/python3.10/importlib/__init__.py", line 126, in import_module
    return _bootstrap._gcd_import(name[level:], package, level)
  File "<frozen importlib._bootstrap>", line 1050, in _gcd_import
  File "<frozen importlib._bootstrap>", line 1027, in _find_and_load
  File "<frozen importlib._bootstrap>", line 1006, in _find_and_load_unlocked
  File "<frozen importlib._bootstrap>", line 688, in _load_unlocked
  File "<frozen importlib._bootstrap_external>", line 883, in exec_module
  File "<frozen importlib._bootstrap>", line 241, in _call_with_frames_removed
  File "/debtfreesolutions/FullRealEstateProject/viewer/urls.py", line 2, in <module>
    from . import views
  File "/debtfreesolutions/FullRealEstateProject/viewer/views.py", line 13
    echo "Starting Gunicorn..."
         ^^^^^^^^^^^^^^^^^^^^^^
SyntaxError: invalid syntax

During handling of the above exception, another exception occurred:

Traceback (most recent call last):
  File "/usr/local/lib/python3.10/dist-packages/django/core/handlers/exception.py", line 55, in inner
    response = get_response(request)
  File "/usr/local/lib/python3.10/dist-packages/django/utils/deprecation.py", line 134, in __call__
    response = response or self.get_response(request)
  File "/usr/local/lib/python3.10/dist-packages/django/core/handlers/exception.py", line 57, in inner
    response = response_for_exception(request, exc)
  File "/usr/local/lib/python3.10/dist-packages/django/core/handlers/exception.py", line 140, in response_for_exception
    response = handle_uncaught_exception(
  File "/usr/local/lib/python3.10/dist-packages/django/core/handlers/exception.py", line 184, in handle_uncaught_exception
    callback = resolver.resolve_error_handler(500)
  File "/usr/local/lib/python3.10/dist-packages/django/urls/resolvers.py", line 752, in resolve_error_handler
    callback = getattr(self.urlconf_module, "handler%s" % view_type, None)
  File "/usr/local/lib/python3.10/dist-packages/django/utils/functional.py", line 47, in __get__
    res = instance.__dict__[self.name] = self.func(instance)
  File "/usr/local/lib/python3.10/dist-packages/django/urls/resolvers.py", line 731, in urlconf_module
    return import_module(self.urlconf_name)
  File "/usr/lib/python3.10/importlib/__init__.py", line 126, in import_module
    return _bootstrap._gcd_import(name[level:], package, level)
  File "<frozen importlib._bootstrap>", line 1050, in _gcd_import
  File "<frozen importlib._bootstrap>", line 1027, in _find_and_load
  File "<frozen importlib._bootstrap>", line 1006, in _find_and_load_unlocked
  File "<frozen importlib._bootstrap>", line 688, in _load_unlocked
  File "<frozen importlib._bootstrap_external>", line 883, in exec_module
  File "<frozen importlib._bootstrap>", line 241, in _call_with_frames_removed
  File "/debtfreesolutions/FullRealEstateProject/FullRealEstateProject/urls.py", line 22, in <module>
    path('', include('viewer.urls')),  # replace 'your_app_name' with the name of your app
  File "/usr/local/lib/python3.10/dist-packages/django/urls/conf.py", line 39, in include
    urlconf_module = import_module(urlconf_module)
  File "/usr/lib/python3.10/importlib/__init__.py", line 126, in import_module
    return _bootstrap._gcd_import(name[level:], package, level)
  File "<frozen importlib._bootstrap>", line 1050, in _gcd_import
  File "<frozen importlib._bootstrap>", line 1027, in _find_and_load
  File "<frozen importlib._bootstrap>", line 1006, in _find_and_load_unlocked
  File "<frozen importlib._bootstrap>", line 688, in _load_unlocked
  File "<frozen importlib._bootstrap_external>", line 883, in exec_module
  File "<frozen importlib._bootstrap>", line 241, in _call_with_frames_removed
  File "/debtfreesolutions/FullRealEstateProject/viewer/urls.py", line 2, in <module>
    from . import views
  File "/debtfreesolutions/FullRealEstateProject/viewer/views.py", line 13
    echo "Starting Gunicorn..."
         ^^^^^^^^^^^^^^^^^^^^^^
SyntaxError: invalid syntax

During handling of the above exception, another exception occurred:

Traceback (most recent call last):
  File "/usr/local/lib/python3.10/dist-packages/django/core/handlers/exception.py", line 55, in inner
    response = get_response(request)
  File "/usr/local/lib/python3.10/dist-packages/django/utils/deprecation.py", line 134, in __call__
    response = response or self.get_response(request)
  File "/usr/local/lib/python3.10/dist-packages/django/core/handlers/exception.py", line 57, in inner
    response = response_for_exception(request, exc)
  File "/usr/local/lib/python3.10/dist-packages/django/core/handlers/exception.py", line 140, in response_for_exception
    response = handle_uncaught_exception(
  File "/usr/local/lib/python3.10/dist-packages/django/core/handlers/exception.py", line 184, in handle_uncaught_exception
    callback = resolver.resolve_error_handler(500)
  File "/usr/local/lib/python3.10/dist-packages/django/urls/resolvers.py", line 752, in resolve_error_handler
    callback = getattr(self.urlconf_module, "handler%s" % view_type, None)
  File "/usr/local/lib/python3.10/dist-packages/django/utils/functional.py", line 47, in __get__
    res = instance.__dict__[self.name] = self.func(instance)
  File "/usr/local/lib/python3.10/dist-packages/django/urls/resolvers.py", line 731, in urlconf_module
    return import_module(self.urlconf_name)
  File "/usr/lib/python3.10/importlib/__init__.py", line 126, in import_module
    return _bootstrap._gcd_import(name[level:], package, level)
  File "<frozen importlib._bootstrap>", line 1050, in _gcd_import
  File "<frozen importlib._bootstrap>", line 1027, in _find_and_load
  File "<frozen importlib._bootstrap>", line 1006, in _find_and_load_unlocked
  File "<frozen importlib._bootstrap>", line 688, in _load_unlocked
  File "<frozen importlib._bootstrap_external>", line 883, in exec_module
  File "<frozen importlib._bootstrap>", line 241, in _call_with_frames_removed
  File "/debtfreesolutions/FullRealEstateProject/FullRealEstateProject/urls.py", line 22, in <module>
    path('', include('viewer.urls')),  # replace 'your_app_name' with the name of your app
  File "/usr/local/lib/python3.10/dist-packages/django/urls/conf.py", line 39, in include
    urlconf_module = import_module(urlconf_module)
  File "/usr/lib/python3.10/importlib/__init__.py", line 126, in import_module
    return _bootstrap._gcd_import(name[level:], package, level)
  File "<frozen importlib._bootstrap>", line 1050, in _gcd_import
  File "<frozen importlib._bootstrap>", line 1027, in _find_and_load
  File "<frozen importlib._bootstrap>", line 1006, in _find_and_load_unlocked
  File "<frozen importlib._bootstrap>", line 688, in _load_unlocked
  File "<frozen importlib._bootstrap_external>", line 883, in exec_module
  File "<frozen importlib._bootstrap>", line 241, in _call_with_frames_removed
  File "/debtfreesolutions/FullRealEstateProject/viewer/urls.py", line 2, in <module>
    from . import views
  File "/debtfreesolutions/FullRealEstateProject/viewer/views.py", line 13
    echo "Starting Gunicorn..."
         ^^^^^^^^^^^^^^^^^^^^^^
SyntaxError: invalid syntax

During handling of the above exception, another exception occurred:

Traceback (most recent call last):
  File "/usr/local/lib/python3.10/dist-packages/django/core/handlers/exception.py", line 55, in inner
    response = get_response(request)
  File "/usr/local/lib/python3.10/dist-packages/django/utils/deprecation.py", line 134, in __call__
    response = response or self.get_response(request)
  File "/usr/local/lib/python3.10/dist-packages/django/core/handlers/exception.py", line 57, in inner
    response = response_for_exception(request, exc)
  File "/usr/local/lib/python3.10/dist-packages/django/core/handlers/exception.py", line 140, in response_for_exception
    response = handle_uncaught_exception(
  File "/usr/local/lib/python3.10/dist-packages/django/core/handlers/exception.py", line 184, in handle_uncaught_exception
    callback = resolver.resolve_error_handler(500)
  File "/usr/local/lib/python3.10/dist-packages/django/urls/resolvers.py", line 752, in resolve_error_handler
    callback = getattr(self.urlconf_module, "handler%s" % view_type, None)
  File "/usr/local/lib/python3.10/dist-packages/django/utils/functional.py", line 47, in __get__
    res = instance.__dict__[self.name] = self.func(instance)
  File "/usr/local/lib/python3.10/dist-packages/django/urls/resolvers.py", line 731, in urlconf_module
    return import_module(self.urlconf_name)
  File "/usr/lib/python3.10/importlib/__init__.py", line 126, in import_module
    return _bootstrap._gcd_import(name[level:], package, level)
  File "<frozen importlib._bootstrap>", line 1050, in _gcd_import
  File "<frozen importlib._bootstrap>", line 1027, in _find_and_load
  File "<frozen importlib._bootstrap>", line 1006, in _find_and_load_unlocked
  File "<frozen importlib._bootstrap>", line 688, in _load_unlocked
  File "<frozen importlib._bootstrap_external>", line 883, in exec_module
  File "<frozen importlib._bootstrap>", line 241, in _call_with_frames_removed
  File "/debtfreesolutions/FullRealEstateProject/FullRealEstateProject/urls.py", line 22, in <module>
    path('', include('viewer.urls')),  # replace 'your_app_name' with the name of your app
  File "/usr/local/lib/python3.10/dist-packages/django/urls/conf.py", line 39, in include
    urlconf_module = import_module(urlconf_module)
  File "/usr/lib/python3.10/importlib/__init__.py", line 126, in import_module
    return _bootstrap._gcd_import(name[level:], package, level)
  File "<frozen importlib._bootstrap>", line 1050, in _gcd_import
  File "<frozen importlib._bootstrap>", line 1027, in _find_and_load
  File "<frozen importlib._bootstrap>", line 1006, in _find_and_load_unlocked
  File "<frozen importlib._bootstrap>", line 688, in _load_unlocked
  File "<frozen importlib._bootstrap_external>", line 883, in exec_module
  File "<frozen importlib._bootstrap>", line 241, in _call_with_frames_removed
  File "/debtfreesolutions/FullRealEstateProject/viewer/urls.py", line 2, in <module>
    from . import views
  File "/debtfreesolutions/FullRealEstateProject/viewer/views.py", line 13
    echo "Starting Gunicorn..."
         ^^^^^^^^^^^^^^^^^^^^^^
SyntaxError: invalid syntax

During handling of the above exception, another exception occurred:

Traceback (most recent call last):
  File "/usr/local/lib/python3.10/dist-packages/gunicorn/workers/sync.py", line 135, in handle
    self.handle_request(listener, req, client, addr)
  File "/usr/local/lib/python3.10/dist-packages/gunicorn/workers/sync.py", line 178, in handle_request
    respiter = self.wsgi(environ, resp.start_response)
  File "/usr/local/lib/python3.10/dist-packages/django/core/handlers/wsgi.py", line 124, in __call__
    response = self.get_response(request)
  File "/usr/local/lib/python3.10/dist-packages/django/core/handlers/base.py", line 140, in get_response
    response = self._middleware_chain(request)
  File "/usr/local/lib/python3.10/dist-packages/django/core/handlers/exception.py", line 57, in inner
    response = response_for_exception(request, exc)
  File "/usr/local/lib/python3.10/dist-packages/django/core/handlers/exception.py", line 140, in response_for_exception
    response = handle_uncaught_exception(
  File "/usr/local/lib/python3.10/dist-packages/django/core/handlers/exception.py", line 184, in handle_uncaught_exception
    callback = resolver.resolve_error_handler(500)
  File "/usr/local/lib/python3.10/dist-packages/django/urls/resolvers.py", line 752, in resolve_error_handler
    callback = getattr(self.urlconf_module, "handler%s" % view_type, None)
  File "/usr/local/lib/python3.10/dist-packages/django/utils/functional.py", line 47, in __get__
    res = instance.__dict__[self.name] = self.func(instance)
  File "/usr/local/lib/python3.10/dist-packages/django/urls/resolvers.py", line 731, in urlconf_module
    return import_module(self.urlconf_name)
  File "/usr/lib/python3.10/importlib/__init__.py", line 126, in import_module
    return _bootstrap._gcd_import(name[level:], package, level)
  File "<frozen importlib._bootstrap>", line 1050, in _gcd_import
  File "<frozen importlib._bootstrap>", line 1027, in _find_and_load
  File "<frozen importlib._bootstrap>", line 1006, in _find_and_load_unlocked
  File "<frozen importlib._bootstrap>", line 688, in _load_unlocked
  File "<frozen importlib._bootstrap_external>", line 883, in exec_module
  File "<frozen importlib._bootstrap>", line 241, in _call_with_frames_removed
  File "/debtfreesolutions/FullRealEstateProject/FullRealEstateProject/urls.py", line 22, in <module>
    path('', include('viewer.urls')),  # replace 'your_app_name' with the name of your app
  File "/usr/local/lib/python3.10/dist-packages/django/urls/conf.py", line 39, in include
    urlconf_module = import_module(urlconf_module)
  File "/usr/lib/python3.10/importlib/__init__.py", line 126, in import_module
    return _bootstrap._gcd_import(name[level:], package, level)
  File "<frozen importlib._bootstrap>", line 1050, in _gcd_import
  File "<frozen importlib._bootstrap>", line 1027, in _find_and_load
  File "<frozen importlib._bootstrap>", line 1006, in _find_and_load_unlocked
  File "<frozen importlib._bootstrap>", line 688, in _load_unlocked
  File "<frozen importlib._bootstrap_external>", line 883, in exec_module
  File "<frozen importlib._bootstrap>", line 241, in _call_with_frames_removed
  File "/debtfreesolutions/FullRealEstateProject/viewer/urls.py", line 2, in <module>
    from . import views
  File "/debtfreesolutions/FullRealEstateProject/viewer/views.py", line 13
    echo "Starting Gunicorn..."
         ^^^^^^^^^^^^^^^^^^^^^^
SyntaxError: invalid syntax
[2024-02-29 22:19:35 +0000] [37866] [INFO] Handling signal: term
[2024-02-29 22:19:35 +0000] [51773] [INFO] Worker exiting (pid: 51773)
[2024-02-29 22:19:35 +0000] [37866] [INFO] Shutting down: Master
Thu Feb 29 10:23:50 PM UTC 2024: Detected change in /debtfreesolutions/FullRealEstateProject/viewer/views.py, reloading Gunicorn...
Thu Feb 29 10:23:50 PM UTC 2024: Detected change in /debtfreesolutions/FullRealEstateProject/viewer/views.py, reloading Gunicorn...
Thu Feb 29 10:23:50 PM UTC 2024: Detected change in /debtfreesolutions/FullRealEstateProject/viewer/views.py, reloading Gunicorn...
Thu Feb 29 10:23:50 PM UTC 2024: PID file not found. Is Gunicorn running?
Thu Feb 29 10:23:50 PM UTC 2024: PID file not found. Is Gunicorn running?
Thu Feb 29 10:23:50 PM UTC 2024: PID file not found. Is Gunicorn running?
